<mujoco>
    <worldbody>
        <light diffuse=".5 .5 .5" pos="0 0 2" dir="0 -1 0"/>
        <geom type="plane" size="10 10 0.1" rgba="0.5 0.7 1 1"/>

        <!-- Main body -->
        <body name="animal_body" pos="0 0 3" euler="0 0 0">
            <joint type="free" axis="0 0 0" pos="0 0 0" />
            <geom type="box" size="0.3 0.85 0.3" rgba="1 0 0 1" mass="0.5" />

            <!-- Legs -->
            <!-- Front Right Leg -->
            <body name="front_right_leg" pos="0.2 0.8 -0.6">
                <joint name="joint_front_right_leg" type="hinge" axis="0 0 1" pos="0 0 0" range="-30 30" />
                <geom type="cylinder" size="0.05 0.5" rgba="0 1 0 1" mass="0.1" />
            </body>
            <!-- Front Left Leg -->
            <body name="front_left_leg" pos="-0.2 0.8 -0.6">
                <joint name="joint_front_left_leg" type="hinge" axis="0 0 1" pos="0 0 0" range="-30 30" />
                <geom type="cylinder" size="0.05 0.5" rgba="0 1 0 1" mass="0.1" />
            </body>
            <!-- Back Right Leg -->
            <body name="back_right_leg" pos="0.2 -0.8 -0.6">
                <joint name="joint_back_right_leg" type="hinge" axis="0 0 1" pos="0 0 0" range="-30 30" />
                <geom type="cylinder" size="0.05 0.5" rgba="0 1 0 1" mass="0.1" />
            </body>
            <!-- Back Left Leg -->
            <body name="back_left_leg" pos="-0.2 -0.8 -0.6">
                <joint name="joint_back_left_leg" type="hinge" axis="0 0 1" pos="0 0 0" range="-30 30" />
                <geom type="cylinder" size="0.05 0.5" rgba="0 1 0 1" mass="0.1" />
            </body>
        </body>
    </worldbody>

    <actuator>
        <motor joint="joint_front_right_leg" name="motor_front_right" gear="10" ctrllimited="true" ctrlrange="-5 5" />
        <motor joint="joint_front_left_leg" name="motor_front_left" gear="10" ctrllimited="true" ctrlrange="-5 5" />
        <motor joint="joint_back_right_leg" name="motor_back_right" gear="10" ctrllimited="true" ctrlrange="-5 5" />
        <motor joint="joint_back_left_leg" name="motor_back_left" gear="10" ctrllimited="true" ctrlrange="-5 5" />
    </actuator>
</mujoco>
